[2024-06-19T12:26:59.893+0000] {local_task_job_runner.py:120} INFO - ::group::Pre task execution logs
[2024-06-19T12:26:59.909+0000] {taskinstance.py:2076} INFO - Dependencies all met for dep_context=non-requeueable deps ti=<TaskInstance: f1_data_create_database_views.read_sql_file manual__2024-06-19T12:26:59.007991+00:00 [queued]>
[2024-06-19T12:26:59.915+0000] {taskinstance.py:2076} INFO - Dependencies all met for dep_context=requeueable deps ti=<TaskInstance: f1_data_create_database_views.read_sql_file manual__2024-06-19T12:26:59.007991+00:00 [queued]>
[2024-06-19T12:26:59.915+0000] {taskinstance.py:2306} INFO - Starting attempt 1 of 2
[2024-06-19T12:26:59.923+0000] {taskinstance.py:2330} INFO - Executing <Task(_PythonDecoratedOperator): read_sql_file> on 2024-06-19 12:26:59.007991+00:00
[2024-06-19T12:26:59.927+0000] {warnings.py:110} WARNING - /home/***/.local/lib/python3.12/site-packages/***/task/task_runner/standard_task_runner.py:61: DeprecationWarning: This process (pid=1506) is multi-threaded, use of fork() may lead to deadlocks in the child.
  pid = os.fork()

[2024-06-19T12:26:59.928+0000] {standard_task_runner.py:63} INFO - Started process 1507 to run task
[2024-06-19T12:26:59.929+0000] {standard_task_runner.py:90} INFO - Running: ['***', 'tasks', 'run', 'f1_data_create_database_views', 'read_sql_file', 'manual__2024-06-19T12:26:59.007991+00:00', '--job-id', '60', '--raw', '--subdir', 'DAGS_FOLDER/database_create_views_task.py', '--cfg-path', '/tmp/tmp2sda540q']
[2024-06-19T12:26:59.929+0000] {standard_task_runner.py:91} INFO - Job 60: Subtask read_sql_file
[2024-06-19T12:26:59.964+0000] {task_command.py:426} INFO - Running <TaskInstance: f1_data_create_database_views.read_sql_file manual__2024-06-19T12:26:59.007991+00:00 [running]> on host eef124934bf8
[2024-06-19T12:27:00.022+0000] {taskinstance.py:2648} INFO - Exporting env vars: AIRFLOW_CTX_DAG_OWNER='***' AIRFLOW_CTX_DAG_ID='f1_data_create_database_views' AIRFLOW_CTX_TASK_ID='read_sql_file' AIRFLOW_CTX_EXECUTION_DATE='2024-06-19T12:26:59.007991+00:00' AIRFLOW_CTX_TRY_NUMBER='1' AIRFLOW_CTX_DAG_RUN_ID='manual__2024-06-19T12:26:59.007991+00:00'
[2024-06-19T12:27:00.023+0000] {taskinstance.py:430} INFO - ::endgroup::
[2024-06-19T12:27:00.023+0000] {taskinstance.py:441} INFO - ::group::Post task execution logs
[2024-06-19T12:27:00.023+0000] {taskinstance.py:2905} ERROR - Task failed with exception
Traceback (most recent call last):
  File "/home/airflow/.local/lib/python3.12/site-packages/airflow/models/taskinstance.py", line 465, in _execute_task
    result = _execute_callable(context=context, **execute_callable_kwargs)
             ^^^^^^^^^^^^^^^^^^^^^^^^^^^^^^^^^^^^^^^^^^^^^^^^^^^^^^^^^^^^^
  File "/home/airflow/.local/lib/python3.12/site-packages/airflow/models/taskinstance.py", line 432, in _execute_callable
    return execute_callable(context=context, **execute_callable_kwargs)
           ^^^^^^^^^^^^^^^^^^^^^^^^^^^^^^^^^^^^^^^^^^^^^^^^^^^^^^^^^^^^
  File "/home/airflow/.local/lib/python3.12/site-packages/airflow/models/baseoperator.py", line 400, in wrapper
    return func(self, *args, **kwargs)
           ^^^^^^^^^^^^^^^^^^^^^^^^^^^
  File "/home/airflow/.local/lib/python3.12/site-packages/airflow/decorators/base.py", line 265, in execute
    return_value = super().execute(context)
                   ^^^^^^^^^^^^^^^^^^^^^^^^
  File "/home/airflow/.local/lib/python3.12/site-packages/airflow/models/baseoperator.py", line 400, in wrapper
    return func(self, *args, **kwargs)
           ^^^^^^^^^^^^^^^^^^^^^^^^^^^
  File "/home/airflow/.local/lib/python3.12/site-packages/airflow/operators/python.py", line 235, in execute
    return_value = self.execute_callable()
                   ^^^^^^^^^^^^^^^^^^^^^^^
  File "/home/airflow/.local/lib/python3.12/site-packages/airflow/operators/python.py", line 252, in execute_callable
    return self.python_callable(*self.op_args, **self.op_kwargs)
           ^^^^^^^^^^^^^^^^^^^^^^^^^^^^^^^^^^^^^^^^^^^^^^^^^^^^^
  File "/opt/airflow/dags/database_create_views_task.py", line 40, in read_sql_file
    with open(sql_path, 'r') as file:
         ^^^^^^^^^^^^^^^^^^^
FileNotFoundError: [Errno 2] No such file or directory: 'sql/DB_views.sql'
[2024-06-19T12:27:00.032+0000] {taskinstance.py:1206} INFO - Marking task as UP_FOR_RETRY. dag_id=f1_data_create_database_views, task_id=read_sql_file, run_id=manual__2024-06-19T12:26:59.007991+00:00, execution_date=20240619T122659, start_date=20240619T122659, end_date=20240619T122700
[2024-06-19T12:27:00.039+0000] {standard_task_runner.py:110} ERROR - Failed to execute job 60 for task read_sql_file ([Errno 2] No such file or directory: 'sql/DB_views.sql'; 1507)
[2024-06-19T12:27:00.061+0000] {local_task_job_runner.py:240} INFO - Task exited with return code 1
[2024-06-19T12:27:00.078+0000] {taskinstance.py:3498} INFO - 0 downstream tasks scheduled from follow-on schedule check
[2024-06-19T12:27:00.079+0000] {local_task_job_runner.py:222} INFO - ::endgroup::
