[2024-06-13T13:57:43.763+0000] {task_context_logger.py:104} ERROR - Executor reports task instance <TaskInstance: f1_data_pipeline_taskflow_with_kafka.wait_for_elt_dag scheduled__2024-06-12T00:00:00+00:00 [queued]> finished (failed) although the task says it's queued. (Info: None) Was the task killed externally?
