[2024-05-31T14:41:25.088+0000] {local_task_job_runner.py:120} INFO - ::group::Pre task execution logs
[2024-05-31T14:41:25.103+0000] {taskinstance.py:2076} INFO - Dependencies all met for dep_context=non-requeueable deps ti=<TaskInstance: f1_data_pipeline_taskflow.load_data__8 scheduled__2024-05-30T00:00:00+00:00 [queued]>
[2024-05-31T14:41:25.108+0000] {taskinstance.py:2076} INFO - Dependencies all met for dep_context=requeueable deps ti=<TaskInstance: f1_data_pipeline_taskflow.load_data__8 scheduled__2024-05-30T00:00:00+00:00 [queued]>
[2024-05-31T14:41:25.109+0000] {taskinstance.py:2306} INFO - Starting attempt 1 of 1
[2024-05-31T14:41:25.117+0000] {taskinstance.py:2330} INFO - Executing <Task(_PythonDecoratedOperator): load_data__8> on 2024-05-30 00:00:00+00:00
[2024-05-31T14:41:25.123+0000] {warnings.py:110} WARNING - /home/***/.local/lib/python3.12/site-packages/***/task/task_runner/standard_task_runner.py:61: DeprecationWarning: This process (pid=399) is multi-threaded, use of fork() may lead to deadlocks in the child.
  pid = os.fork()

[2024-05-31T14:41:25.124+0000] {standard_task_runner.py:63} INFO - Started process 402 to run task
[2024-05-31T14:41:25.124+0000] {standard_task_runner.py:90} INFO - Running: ['***', 'tasks', 'run', 'f1_data_pipeline_taskflow', 'load_data__8', 'scheduled__2024-05-30T00:00:00+00:00', '--job-id', '21', '--raw', '--subdir', 'DAGS_FOLDER/etl_dag.py', '--cfg-path', '/tmp/tmp91tlmam7']
[2024-05-31T14:41:25.126+0000] {standard_task_runner.py:91} INFO - Job 21: Subtask load_data__8
[2024-05-31T14:41:25.160+0000] {task_command.py:426} INFO - Running <TaskInstance: f1_data_pipeline_taskflow.load_data__8 scheduled__2024-05-30T00:00:00+00:00 [running]> on host 39ebc24e8ca6
[2024-05-31T14:41:25.260+0000] {taskinstance.py:2648} INFO - Exporting env vars: AIRFLOW_CTX_DAG_OWNER='***' AIRFLOW_CTX_DAG_ID='f1_data_pipeline_taskflow' AIRFLOW_CTX_TASK_ID='load_data__8' AIRFLOW_CTX_EXECUTION_DATE='2024-05-30T00:00:00+00:00' AIRFLOW_CTX_TRY_NUMBER='1' AIRFLOW_CTX_DAG_RUN_ID='scheduled__2024-05-30T00:00:00+00:00'
[2024-05-31T14:41:25.261+0000] {taskinstance.py:430} INFO - ::endgroup::
[2024-05-31T14:41:25.262+0000] {crypto.py:82} WARNING - empty cryptography key - values will not be stored encrypted.
[2024-05-31T14:41:25.263+0000] {base.py:84} INFO - Using connection ID 'sourcedb_connection' for task execution.
[2024-05-31T14:41:25.271+0000] {warnings.py:110} WARNING - /opt/***/dags/etl_dag.py:160: UserWarning: the 'timedelta' type is not supported, and will be written as integer values (ns frequency) to the database.
  df.to_sql(table_name, engine, if_exists='append', index=False)

[2024-05-31T14:41:25.405+0000] {python.py:237} INFO - Done. Returned value was: None
[2024-05-31T14:41:25.405+0000] {taskinstance.py:441} INFO - ::group::Post task execution logs
[2024-05-31T14:41:25.412+0000] {taskinstance.py:1206} INFO - Marking task as SUCCESS. dag_id=f1_data_pipeline_taskflow, task_id=load_data__8, run_id=scheduled__2024-05-30T00:00:00+00:00, execution_date=20240530T000000, start_date=20240531T144125, end_date=20240531T144125
[2024-05-31T14:41:25.458+0000] {local_task_job_runner.py:240} INFO - Task exited with return code 0
[2024-05-31T14:41:25.469+0000] {taskinstance.py:3498} INFO - 0 downstream tasks scheduled from follow-on schedule check
[2024-05-31T14:41:25.470+0000] {local_task_job_runner.py:222} INFO - ::endgroup::
[2024-05-31T14:44:45.589+0000] {local_task_job_runner.py:120} INFO - ::group::Pre task execution logs
[2024-05-31T14:44:45.610+0000] {taskinstance.py:2076} INFO - Dependencies all met for dep_context=non-requeueable deps ti=<TaskInstance: f1_data_pipeline_taskflow.load_data__8 scheduled__2024-05-30T00:00:00+00:00 [queued]>
[2024-05-31T14:44:45.618+0000] {taskinstance.py:2076} INFO - Dependencies all met for dep_context=requeueable deps ti=<TaskInstance: f1_data_pipeline_taskflow.load_data__8 scheduled__2024-05-30T00:00:00+00:00 [queued]>
[2024-05-31T14:44:45.618+0000] {taskinstance.py:2306} INFO - Starting attempt 1 of 1
[2024-05-31T14:44:45.629+0000] {taskinstance.py:2330} INFO - Executing <Task(_PythonDecoratedOperator): load_data__8> on 2024-05-30 00:00:00+00:00
[2024-05-31T14:44:45.637+0000] {warnings.py:110} WARNING - /home/***/.local/lib/python3.12/site-packages/***/task/task_runner/standard_task_runner.py:61: DeprecationWarning: This process (pid=398) is multi-threaded, use of fork() may lead to deadlocks in the child.
  pid = os.fork()

[2024-05-31T14:44:45.638+0000] {standard_task_runner.py:63} INFO - Started process 401 to run task
[2024-05-31T14:44:45.638+0000] {standard_task_runner.py:90} INFO - Running: ['***', 'tasks', 'run', 'f1_data_pipeline_taskflow', 'load_data__8', 'scheduled__2024-05-30T00:00:00+00:00', '--job-id', '20', '--raw', '--subdir', 'DAGS_FOLDER/etl_dag.py', '--cfg-path', '/tmp/tmpc08f3qdi']
[2024-05-31T14:44:45.640+0000] {standard_task_runner.py:91} INFO - Job 20: Subtask load_data__8
[2024-05-31T14:44:45.680+0000] {task_command.py:426} INFO - Running <TaskInstance: f1_data_pipeline_taskflow.load_data__8 scheduled__2024-05-30T00:00:00+00:00 [running]> on host a9750641015b
[2024-05-31T14:44:45.780+0000] {taskinstance.py:2648} INFO - Exporting env vars: AIRFLOW_CTX_DAG_OWNER='***' AIRFLOW_CTX_DAG_ID='f1_data_pipeline_taskflow' AIRFLOW_CTX_TASK_ID='load_data__8' AIRFLOW_CTX_EXECUTION_DATE='2024-05-30T00:00:00+00:00' AIRFLOW_CTX_TRY_NUMBER='1' AIRFLOW_CTX_DAG_RUN_ID='scheduled__2024-05-30T00:00:00+00:00'
[2024-05-31T14:44:45.781+0000] {taskinstance.py:430} INFO - ::endgroup::
[2024-05-31T14:44:45.782+0000] {crypto.py:82} WARNING - empty cryptography key - values will not be stored encrypted.
[2024-05-31T14:44:45.782+0000] {base.py:84} INFO - Using connection ID 'sourcedb_connection' for task execution.
[2024-05-31T14:44:45.791+0000] {warnings.py:110} WARNING - /opt/***/dags/etl_dag.py:160: UserWarning: the 'timedelta' type is not supported, and will be written as integer values (ns frequency) to the database.
  df.to_sql(table_name, engine, if_exists='append', index=False)

[2024-05-31T14:44:45.841+0000] {taskinstance.py:441} INFO - ::group::Post task execution logs
[2024-05-31T14:44:45.842+0000] {taskinstance.py:2905} ERROR - Task failed with exception
Traceback (most recent call last):
  File "/home/airflow/.local/lib/python3.12/site-packages/sqlalchemy/engine/base.py", line 1890, in _execute_context
    self.dialect.do_executemany(
  File "/home/airflow/.local/lib/python3.12/site-packages/sqlalchemy/dialects/postgresql/psycopg2.py", line 982, in do_executemany
    context._psycopg2_fetched_rows = xtras.execute_values(
                                     ^^^^^^^^^^^^^^^^^^^^^
  File "/home/airflow/.local/lib/python3.12/site-packages/psycopg2/extras.py", line 1299, in execute_values
    cur.execute(b''.join(parts))
psycopg2.errors.DatatypeMismatch: column "duration" is of type time without time zone but expression is of type bigint
LINE 1: ...nds_pitstops) VALUES (860, 18, 1, 16, '17:28:30', 2327500000...
                                                             ^
HINT:  You will need to rewrite or cast the expression.


The above exception was the direct cause of the following exception:

Traceback (most recent call last):
  File "/home/airflow/.local/lib/python3.12/site-packages/airflow/models/taskinstance.py", line 465, in _execute_task
    result = _execute_callable(context=context, **execute_callable_kwargs)
             ^^^^^^^^^^^^^^^^^^^^^^^^^^^^^^^^^^^^^^^^^^^^^^^^^^^^^^^^^^^^^
  File "/home/airflow/.local/lib/python3.12/site-packages/airflow/models/taskinstance.py", line 432, in _execute_callable
    return execute_callable(context=context, **execute_callable_kwargs)
           ^^^^^^^^^^^^^^^^^^^^^^^^^^^^^^^^^^^^^^^^^^^^^^^^^^^^^^^^^^^^
  File "/home/airflow/.local/lib/python3.12/site-packages/airflow/models/baseoperator.py", line 400, in wrapper
    return func(self, *args, **kwargs)
           ^^^^^^^^^^^^^^^^^^^^^^^^^^^
  File "/home/airflow/.local/lib/python3.12/site-packages/airflow/decorators/base.py", line 265, in execute
    return_value = super().execute(context)
                   ^^^^^^^^^^^^^^^^^^^^^^^^
  File "/home/airflow/.local/lib/python3.12/site-packages/airflow/models/baseoperator.py", line 400, in wrapper
    return func(self, *args, **kwargs)
           ^^^^^^^^^^^^^^^^^^^^^^^^^^^
  File "/home/airflow/.local/lib/python3.12/site-packages/airflow/operators/python.py", line 235, in execute
    return_value = self.execute_callable()
                   ^^^^^^^^^^^^^^^^^^^^^^^
  File "/home/airflow/.local/lib/python3.12/site-packages/airflow/operators/python.py", line 252, in execute_callable
    return self.python_callable(*self.op_args, **self.op_kwargs)
           ^^^^^^^^^^^^^^^^^^^^^^^^^^^^^^^^^^^^^^^^^^^^^^^^^^^^^
  File "/opt/airflow/dags/etl_dag.py", line 160, in load_data
    df.to_sql(table_name, engine, if_exists='append', index=False)
  File "/home/airflow/.local/lib/python3.12/site-packages/pandas/util/_decorators.py", line 333, in wrapper
    return func(*args, **kwargs)
           ^^^^^^^^^^^^^^^^^^^^^
  File "/home/airflow/.local/lib/python3.12/site-packages/pandas/core/generic.py", line 3008, in to_sql
    return sql.to_sql(
           ^^^^^^^^^^^
  File "/home/airflow/.local/lib/python3.12/site-packages/pandas/io/sql.py", line 788, in to_sql
    return pandas_sql.to_sql(
           ^^^^^^^^^^^^^^^^^^
  File "/home/airflow/.local/lib/python3.12/site-packages/pandas/io/sql.py", line 1958, in to_sql
    total_inserted = sql_engine.insert_records(
                     ^^^^^^^^^^^^^^^^^^^^^^^^^^
  File "/home/airflow/.local/lib/python3.12/site-packages/pandas/io/sql.py", line 1507, in insert_records
    raise err
  File "/home/airflow/.local/lib/python3.12/site-packages/pandas/io/sql.py", line 1498, in insert_records
    return table.insert(chunksize=chunksize, method=method)
           ^^^^^^^^^^^^^^^^^^^^^^^^^^^^^^^^^^^^^^^^^^^^^^^^
  File "/home/airflow/.local/lib/python3.12/site-packages/pandas/io/sql.py", line 1059, in insert
    num_inserted = exec_insert(conn, keys, chunk_iter)
                   ^^^^^^^^^^^^^^^^^^^^^^^^^^^^^^^^^^^
  File "/home/airflow/.local/lib/python3.12/site-packages/pandas/io/sql.py", line 951, in _execute_insert
    result = conn.execute(self.table.insert(), data)
             ^^^^^^^^^^^^^^^^^^^^^^^^^^^^^^^^^^^^^^^
  File "/home/airflow/.local/lib/python3.12/site-packages/sqlalchemy/engine/base.py", line 1385, in execute
    return meth(self, multiparams, params, _EMPTY_EXECUTION_OPTS)
           ^^^^^^^^^^^^^^^^^^^^^^^^^^^^^^^^^^^^^^^^^^^^^^^^^^^^^^
  File "/home/airflow/.local/lib/python3.12/site-packages/sqlalchemy/sql/elements.py", line 334, in _execute_on_connection
    return connection._execute_clauseelement(
           ^^^^^^^^^^^^^^^^^^^^^^^^^^^^^^^^^^
  File "/home/airflow/.local/lib/python3.12/site-packages/sqlalchemy/engine/base.py", line 1577, in _execute_clauseelement
    ret = self._execute_context(
          ^^^^^^^^^^^^^^^^^^^^^^
  File "/home/airflow/.local/lib/python3.12/site-packages/sqlalchemy/engine/base.py", line 1953, in _execute_context
    self._handle_dbapi_exception(
  File "/home/airflow/.local/lib/python3.12/site-packages/sqlalchemy/engine/base.py", line 2134, in _handle_dbapi_exception
    util.raise_(
  File "/home/airflow/.local/lib/python3.12/site-packages/sqlalchemy/util/compat.py", line 211, in raise_
    raise exception
  File "/home/airflow/.local/lib/python3.12/site-packages/sqlalchemy/engine/base.py", line 1890, in _execute_context
    self.dialect.do_executemany(
  File "/home/airflow/.local/lib/python3.12/site-packages/sqlalchemy/dialects/postgresql/psycopg2.py", line 982, in do_executemany
    context._psycopg2_fetched_rows = xtras.execute_values(
                                     ^^^^^^^^^^^^^^^^^^^^^
  File "/home/airflow/.local/lib/python3.12/site-packages/psycopg2/extras.py", line 1299, in execute_values
    cur.execute(b''.join(parts))
sqlalchemy.exc.ProgrammingError: (psycopg2.errors.DatatypeMismatch) column "duration" is of type time without time zone but expression is of type bigint
LINE 1: ...nds_pitstops) VALUES (860, 18, 1, 16, '17:28:30', 2327500000...
                                                             ^
HINT:  You will need to rewrite or cast the expression.

[SQL: INSERT INTO "pitStopsDim" ("raceId", "driverId", stop, lap_pitstops, time_pitstops, duration, milliseconds_pitstops) VALUES (%(raceId)s, %(driverId)s, %(stop)s, %(lap_pitstops)s, %(time_pitstops)s, %(duration)s, %(milliseconds_pitstops)s)]
[parameters: ({'raceId': 860, 'driverId': 18, 'stop': 1, 'lap_pitstops': 16, 'time_pitstops': '17:28:30', 'duration': 23275000000, 'milliseconds_pitstops': 23275}, {'raceId': 860, 'driverId': 18, 'stop': 2, 'lap_pitstops': 36, 'time_pitstops': '17:59:44', 'duration': 22837000000, 'milliseconds_pitstops': 22837}, {'raceId': 860, 'driverId': 1, 'stop': 1, 'lap_pitstops': 17, 'time_pitstops': '17:30:12', 'duration': 22862000000, 'milliseconds_pitstops': 22862}, {'raceId': 860, 'driverId': 1, 'stop': 2, 'lap_pitstops': 36, 'time_pitstops': '17:59:54', 'duration': 23464000000, 'milliseconds_pitstops': 23464}, {'raceId': 861, 'driverId': 18, 'stop': 1, 'lap_pitstops': 4, 'time_pitstops': '16:12:01', 'duration': 24305000000, 'milliseconds_pitstops': 24305}, {'raceId': 861, 'driverId': 18, 'stop': 2, 'lap_pitstops': 13, 'time_pitstops': '17:26:27', 'duration': 25922000000, 'milliseconds_pitstops': 25922}, {'raceId': 861, 'driverId': 18, 'stop': 3, 'lap_pitstops': 15, 'time_pitstops': '17:31:07', 'duration': 36517000000, 'milliseconds_pitstops': 36517}, {'raceId': 861, 'driverId': 18, 'stop': 4, 'lap_pitstops': 24, 'time_pitstops': '17:50:04', 'duration': 23509000000, 'milliseconds_pitstops': 23509}  ... displaying 10 of 8975 total bound parameter sets ...  {'raceId': 953, 'driverId': 837, 'stop': 2, 'lap_pitstops': 34, 'time_pitstops': '15:00:18', 'duration': 27380000000, 'milliseconds_pitstops': 27380}, {'raceId': 953, 'driverId': 837, 'stop': 3, 'lap_pitstops': 47, 'time_pitstops': '15:21:24', 'duration': 26292000000, 'milliseconds_pitstops': 26292})]
(Background on this error at: https://sqlalche.me/e/14/f405)
[2024-05-31T14:44:45.858+0000] {taskinstance.py:1206} INFO - Marking task as FAILED. dag_id=f1_data_pipeline_taskflow, task_id=load_data__8, run_id=scheduled__2024-05-30T00:00:00+00:00, execution_date=20240530T000000, start_date=20240531T144445, end_date=20240531T144445
[2024-05-31T14:44:45.866+0000] {standard_task_runner.py:110} ERROR - Failed to execute job 20 for task load_data__8 ((psycopg2.errors.DatatypeMismatch) column "duration" is of type time without time zone but expression is of type bigint
LINE 1: ...nds_pitstops) VALUES (860, 18, 1, 16, '17:28:30', 2327500000...
                                                             ^
HINT:  You will need to rewrite or cast the expression.

[SQL: INSERT INTO "pitStopsDim" ("raceId", "driverId", stop, lap_pitstops, time_pitstops, duration, milliseconds_pitstops) VALUES (%(raceId)s, %(driverId)s, %(stop)s, %(lap_pitstops)s, %(time_pitstops)s, %(duration)s, %(milliseconds_pitstops)s)]
[parameters: ({'raceId': 860, 'driverId': 18, 'stop': 1, 'lap_pitstops': 16, 'time_pitstops': '17:28:30', 'duration': 23275000000, 'milliseconds_pitstops': 23275}, {'raceId': 860, 'driverId': 18, 'stop': 2, 'lap_pitstops': 36, 'time_pitstops': '17:59:44', 'duration': 22837000000, 'milliseconds_pitstops': 22837}, {'raceId': 860, 'driverId': 1, 'stop': 1, 'lap_pitstops': 17, 'time_pitstops': '17:30:12', 'duration': 22862000000, 'milliseconds_pitstops': 22862}, {'raceId': 860, 'driverId': 1, 'stop': 2, 'lap_pitstops': 36, 'time_pitstops': '17:59:54', 'duration': 23464000000, 'milliseconds_pitstops': 23464}, {'raceId': 861, 'driverId': 18, 'stop': 1, 'lap_pitstops': 4, 'time_pitstops': '16:12:01', 'duration': 24305000000, 'milliseconds_pitstops': 24305}, {'raceId': 861, 'driverId': 18, 'stop': 2, 'lap_pitstops': 13, 'time_pitstops': '17:26:27', 'duration': 25922000000, 'milliseconds_pitstops': 25922}, {'raceId': 861, 'driverId': 18, 'stop': 3, 'lap_pitstops': 15, 'time_pitstops': '17:31:07', 'duration': 36517000000, 'milliseconds_pitstops': 36517}, {'raceId': 861, 'driverId': 18, 'stop': 4, 'lap_pitstops': 24, 'time_pitstops': '17:50:04', 'duration': 23509000000, 'milliseconds_pitstops': 23509}  ... displaying 10 of 8975 total bound parameter sets ...  {'raceId': 953, 'driverId': 837, 'stop': 2, 'lap_pitstops': 34, 'time_pitstops': '15:00:18', 'duration': 27380000000, 'milliseconds_pitstops': 27380}, {'raceId': 953, 'driverId': 837, 'stop': 3, 'lap_pitstops': 47, 'time_pitstops': '15:21:24', 'duration': 26292000000, 'milliseconds_pitstops': 26292})]
(Background on this error at: https://sqlalche.me/e/14/f405); 401)
[2024-05-31T14:44:45.891+0000] {local_task_job_runner.py:240} INFO - Task exited with return code 1
[2024-05-31T14:44:45.903+0000] {taskinstance.py:3498} INFO - 0 downstream tasks scheduled from follow-on schedule check
[2024-05-31T14:44:45.905+0000] {local_task_job_runner.py:222} INFO - ::endgroup::
[2024-05-31T14:48:51.262+0000] {local_task_job_runner.py:120} INFO - ::group::Pre task execution logs
[2024-05-31T14:48:51.278+0000] {taskinstance.py:2076} INFO - Dependencies all met for dep_context=non-requeueable deps ti=<TaskInstance: f1_data_pipeline_taskflow.load_data__8 scheduled__2024-05-30T00:00:00+00:00 [queued]>
[2024-05-31T14:48:51.284+0000] {taskinstance.py:2076} INFO - Dependencies all met for dep_context=requeueable deps ti=<TaskInstance: f1_data_pipeline_taskflow.load_data__8 scheduled__2024-05-30T00:00:00+00:00 [queued]>
[2024-05-31T14:48:51.284+0000] {taskinstance.py:2306} INFO - Starting attempt 1 of 1
[2024-05-31T14:48:51.292+0000] {taskinstance.py:2330} INFO - Executing <Task(_PythonDecoratedOperator): load_data__8> on 2024-05-30 00:00:00+00:00
[2024-05-31T14:48:51.298+0000] {warnings.py:110} WARNING - /home/***/.local/lib/python3.12/site-packages/***/task/task_runner/standard_task_runner.py:61: DeprecationWarning: This process (pid=397) is multi-threaded, use of fork() may lead to deadlocks in the child.
  pid = os.fork()

[2024-05-31T14:48:51.299+0000] {standard_task_runner.py:63} INFO - Started process 401 to run task
[2024-05-31T14:48:51.299+0000] {standard_task_runner.py:90} INFO - Running: ['***', 'tasks', 'run', 'f1_data_pipeline_taskflow', 'load_data__8', 'scheduled__2024-05-30T00:00:00+00:00', '--job-id', '20', '--raw', '--subdir', 'DAGS_FOLDER/etl_dag.py', '--cfg-path', '/tmp/tmpd1ifpxz_']
[2024-05-31T14:48:51.301+0000] {standard_task_runner.py:91} INFO - Job 20: Subtask load_data__8
[2024-05-31T14:48:51.334+0000] {task_command.py:426} INFO - Running <TaskInstance: f1_data_pipeline_taskflow.load_data__8 scheduled__2024-05-30T00:00:00+00:00 [running]> on host 5e099e29bc21
[2024-05-31T14:48:51.442+0000] {taskinstance.py:2648} INFO - Exporting env vars: AIRFLOW_CTX_DAG_OWNER='***' AIRFLOW_CTX_DAG_ID='f1_data_pipeline_taskflow' AIRFLOW_CTX_TASK_ID='load_data__8' AIRFLOW_CTX_EXECUTION_DATE='2024-05-30T00:00:00+00:00' AIRFLOW_CTX_TRY_NUMBER='1' AIRFLOW_CTX_DAG_RUN_ID='scheduled__2024-05-30T00:00:00+00:00'
[2024-05-31T14:48:51.443+0000] {taskinstance.py:430} INFO - ::endgroup::
[2024-05-31T14:48:51.444+0000] {crypto.py:82} WARNING - empty cryptography key - values will not be stored encrypted.
[2024-05-31T14:48:51.444+0000] {base.py:84} INFO - Using connection ID 'sourcedb_connection' for task execution.
[2024-05-31T14:48:51.452+0000] {warnings.py:110} WARNING - /opt/***/dags/etl_dag.py:160: UserWarning: the 'timedelta' type is not supported, and will be written as integer values (ns frequency) to the database.
  df.to_sql(table_name, engine, if_exists='append', index=False)

[2024-05-31T14:48:51.501+0000] {taskinstance.py:441} INFO - ::group::Post task execution logs
[2024-05-31T14:48:51.502+0000] {taskinstance.py:2905} ERROR - Task failed with exception
Traceback (most recent call last):
  File "/home/airflow/.local/lib/python3.12/site-packages/sqlalchemy/engine/base.py", line 1890, in _execute_context
    self.dialect.do_executemany(
  File "/home/airflow/.local/lib/python3.12/site-packages/sqlalchemy/dialects/postgresql/psycopg2.py", line 982, in do_executemany
    context._psycopg2_fetched_rows = xtras.execute_values(
                                     ^^^^^^^^^^^^^^^^^^^^^
  File "/home/airflow/.local/lib/python3.12/site-packages/psycopg2/extras.py", line 1299, in execute_values
    cur.execute(b''.join(parts))
psycopg2.errors.DatatypeMismatch: column "duration" is of type timestamp with time zone but expression is of type bigint
LINE 1: ...nds_pitstops) VALUES (860, 18, 1, 16, '17:28:30', 2327500000...
                                                             ^
HINT:  You will need to rewrite or cast the expression.


The above exception was the direct cause of the following exception:

Traceback (most recent call last):
  File "/home/airflow/.local/lib/python3.12/site-packages/airflow/models/taskinstance.py", line 465, in _execute_task
    result = _execute_callable(context=context, **execute_callable_kwargs)
             ^^^^^^^^^^^^^^^^^^^^^^^^^^^^^^^^^^^^^^^^^^^^^^^^^^^^^^^^^^^^^
  File "/home/airflow/.local/lib/python3.12/site-packages/airflow/models/taskinstance.py", line 432, in _execute_callable
    return execute_callable(context=context, **execute_callable_kwargs)
           ^^^^^^^^^^^^^^^^^^^^^^^^^^^^^^^^^^^^^^^^^^^^^^^^^^^^^^^^^^^^
  File "/home/airflow/.local/lib/python3.12/site-packages/airflow/models/baseoperator.py", line 400, in wrapper
    return func(self, *args, **kwargs)
           ^^^^^^^^^^^^^^^^^^^^^^^^^^^
  File "/home/airflow/.local/lib/python3.12/site-packages/airflow/decorators/base.py", line 265, in execute
    return_value = super().execute(context)
                   ^^^^^^^^^^^^^^^^^^^^^^^^
  File "/home/airflow/.local/lib/python3.12/site-packages/airflow/models/baseoperator.py", line 400, in wrapper
    return func(self, *args, **kwargs)
           ^^^^^^^^^^^^^^^^^^^^^^^^^^^
  File "/home/airflow/.local/lib/python3.12/site-packages/airflow/operators/python.py", line 235, in execute
    return_value = self.execute_callable()
                   ^^^^^^^^^^^^^^^^^^^^^^^
  File "/home/airflow/.local/lib/python3.12/site-packages/airflow/operators/python.py", line 252, in execute_callable
    return self.python_callable(*self.op_args, **self.op_kwargs)
           ^^^^^^^^^^^^^^^^^^^^^^^^^^^^^^^^^^^^^^^^^^^^^^^^^^^^^
  File "/opt/airflow/dags/etl_dag.py", line 160, in load_data
    df.to_sql(table_name, engine, if_exists='append', index=False)
  File "/home/airflow/.local/lib/python3.12/site-packages/pandas/util/_decorators.py", line 333, in wrapper
    return func(*args, **kwargs)
           ^^^^^^^^^^^^^^^^^^^^^
  File "/home/airflow/.local/lib/python3.12/site-packages/pandas/core/generic.py", line 3008, in to_sql
    return sql.to_sql(
           ^^^^^^^^^^^
  File "/home/airflow/.local/lib/python3.12/site-packages/pandas/io/sql.py", line 788, in to_sql
    return pandas_sql.to_sql(
           ^^^^^^^^^^^^^^^^^^
  File "/home/airflow/.local/lib/python3.12/site-packages/pandas/io/sql.py", line 1958, in to_sql
    total_inserted = sql_engine.insert_records(
                     ^^^^^^^^^^^^^^^^^^^^^^^^^^
  File "/home/airflow/.local/lib/python3.12/site-packages/pandas/io/sql.py", line 1507, in insert_records
    raise err
  File "/home/airflow/.local/lib/python3.12/site-packages/pandas/io/sql.py", line 1498, in insert_records
    return table.insert(chunksize=chunksize, method=method)
           ^^^^^^^^^^^^^^^^^^^^^^^^^^^^^^^^^^^^^^^^^^^^^^^^
  File "/home/airflow/.local/lib/python3.12/site-packages/pandas/io/sql.py", line 1059, in insert
    num_inserted = exec_insert(conn, keys, chunk_iter)
                   ^^^^^^^^^^^^^^^^^^^^^^^^^^^^^^^^^^^
  File "/home/airflow/.local/lib/python3.12/site-packages/pandas/io/sql.py", line 951, in _execute_insert
    result = conn.execute(self.table.insert(), data)
             ^^^^^^^^^^^^^^^^^^^^^^^^^^^^^^^^^^^^^^^
  File "/home/airflow/.local/lib/python3.12/site-packages/sqlalchemy/engine/base.py", line 1385, in execute
    return meth(self, multiparams, params, _EMPTY_EXECUTION_OPTS)
           ^^^^^^^^^^^^^^^^^^^^^^^^^^^^^^^^^^^^^^^^^^^^^^^^^^^^^^
  File "/home/airflow/.local/lib/python3.12/site-packages/sqlalchemy/sql/elements.py", line 334, in _execute_on_connection
    return connection._execute_clauseelement(
           ^^^^^^^^^^^^^^^^^^^^^^^^^^^^^^^^^^
  File "/home/airflow/.local/lib/python3.12/site-packages/sqlalchemy/engine/base.py", line 1577, in _execute_clauseelement
    ret = self._execute_context(
          ^^^^^^^^^^^^^^^^^^^^^^
  File "/home/airflow/.local/lib/python3.12/site-packages/sqlalchemy/engine/base.py", line 1953, in _execute_context
    self._handle_dbapi_exception(
  File "/home/airflow/.local/lib/python3.12/site-packages/sqlalchemy/engine/base.py", line 2134, in _handle_dbapi_exception
    util.raise_(
  File "/home/airflow/.local/lib/python3.12/site-packages/sqlalchemy/util/compat.py", line 211, in raise_
    raise exception
  File "/home/airflow/.local/lib/python3.12/site-packages/sqlalchemy/engine/base.py", line 1890, in _execute_context
    self.dialect.do_executemany(
  File "/home/airflow/.local/lib/python3.12/site-packages/sqlalchemy/dialects/postgresql/psycopg2.py", line 982, in do_executemany
    context._psycopg2_fetched_rows = xtras.execute_values(
                                     ^^^^^^^^^^^^^^^^^^^^^
  File "/home/airflow/.local/lib/python3.12/site-packages/psycopg2/extras.py", line 1299, in execute_values
    cur.execute(b''.join(parts))
sqlalchemy.exc.ProgrammingError: (psycopg2.errors.DatatypeMismatch) column "duration" is of type timestamp with time zone but expression is of type bigint
LINE 1: ...nds_pitstops) VALUES (860, 18, 1, 16, '17:28:30', 2327500000...
                                                             ^
HINT:  You will need to rewrite or cast the expression.

[SQL: INSERT INTO "pitStopsDim" ("raceId", "driverId", stop, lap_pitstops, time_pitstops, duration, milliseconds_pitstops) VALUES (%(raceId)s, %(driverId)s, %(stop)s, %(lap_pitstops)s, %(time_pitstops)s, %(duration)s, %(milliseconds_pitstops)s)]
[parameters: ({'raceId': 860, 'driverId': 18, 'stop': 1, 'lap_pitstops': 16, 'time_pitstops': '17:28:30', 'duration': 23275000000, 'milliseconds_pitstops': 23275}, {'raceId': 860, 'driverId': 18, 'stop': 2, 'lap_pitstops': 36, 'time_pitstops': '17:59:44', 'duration': 22837000000, 'milliseconds_pitstops': 22837}, {'raceId': 860, 'driverId': 1, 'stop': 1, 'lap_pitstops': 17, 'time_pitstops': '17:30:12', 'duration': 22862000000, 'milliseconds_pitstops': 22862}, {'raceId': 860, 'driverId': 1, 'stop': 2, 'lap_pitstops': 36, 'time_pitstops': '17:59:54', 'duration': 23464000000, 'milliseconds_pitstops': 23464}, {'raceId': 861, 'driverId': 18, 'stop': 1, 'lap_pitstops': 4, 'time_pitstops': '16:12:01', 'duration': 24305000000, 'milliseconds_pitstops': 24305}, {'raceId': 861, 'driverId': 18, 'stop': 2, 'lap_pitstops': 13, 'time_pitstops': '17:26:27', 'duration': 25922000000, 'milliseconds_pitstops': 25922}, {'raceId': 861, 'driverId': 18, 'stop': 3, 'lap_pitstops': 15, 'time_pitstops': '17:31:07', 'duration': 36517000000, 'milliseconds_pitstops': 36517}, {'raceId': 861, 'driverId': 18, 'stop': 4, 'lap_pitstops': 24, 'time_pitstops': '17:50:04', 'duration': 23509000000, 'milliseconds_pitstops': 23509}  ... displaying 10 of 8975 total bound parameter sets ...  {'raceId': 953, 'driverId': 837, 'stop': 2, 'lap_pitstops': 34, 'time_pitstops': '15:00:18', 'duration': 27380000000, 'milliseconds_pitstops': 27380}, {'raceId': 953, 'driverId': 837, 'stop': 3, 'lap_pitstops': 47, 'time_pitstops': '15:21:24', 'duration': 26292000000, 'milliseconds_pitstops': 26292})]
(Background on this error at: https://sqlalche.me/e/14/f405)
[2024-05-31T14:48:51.519+0000] {taskinstance.py:1206} INFO - Marking task as FAILED. dag_id=f1_data_pipeline_taskflow, task_id=load_data__8, run_id=scheduled__2024-05-30T00:00:00+00:00, execution_date=20240530T000000, start_date=20240531T144851, end_date=20240531T144851
[2024-05-31T14:48:51.528+0000] {standard_task_runner.py:110} ERROR - Failed to execute job 20 for task load_data__8 ((psycopg2.errors.DatatypeMismatch) column "duration" is of type timestamp with time zone but expression is of type bigint
LINE 1: ...nds_pitstops) VALUES (860, 18, 1, 16, '17:28:30', 2327500000...
                                                             ^
HINT:  You will need to rewrite or cast the expression.

[SQL: INSERT INTO "pitStopsDim" ("raceId", "driverId", stop, lap_pitstops, time_pitstops, duration, milliseconds_pitstops) VALUES (%(raceId)s, %(driverId)s, %(stop)s, %(lap_pitstops)s, %(time_pitstops)s, %(duration)s, %(milliseconds_pitstops)s)]
[parameters: ({'raceId': 860, 'driverId': 18, 'stop': 1, 'lap_pitstops': 16, 'time_pitstops': '17:28:30', 'duration': 23275000000, 'milliseconds_pitstops': 23275}, {'raceId': 860, 'driverId': 18, 'stop': 2, 'lap_pitstops': 36, 'time_pitstops': '17:59:44', 'duration': 22837000000, 'milliseconds_pitstops': 22837}, {'raceId': 860, 'driverId': 1, 'stop': 1, 'lap_pitstops': 17, 'time_pitstops': '17:30:12', 'duration': 22862000000, 'milliseconds_pitstops': 22862}, {'raceId': 860, 'driverId': 1, 'stop': 2, 'lap_pitstops': 36, 'time_pitstops': '17:59:54', 'duration': 23464000000, 'milliseconds_pitstops': 23464}, {'raceId': 861, 'driverId': 18, 'stop': 1, 'lap_pitstops': 4, 'time_pitstops': '16:12:01', 'duration': 24305000000, 'milliseconds_pitstops': 24305}, {'raceId': 861, 'driverId': 18, 'stop': 2, 'lap_pitstops': 13, 'time_pitstops': '17:26:27', 'duration': 25922000000, 'milliseconds_pitstops': 25922}, {'raceId': 861, 'driverId': 18, 'stop': 3, 'lap_pitstops': 15, 'time_pitstops': '17:31:07', 'duration': 36517000000, 'milliseconds_pitstops': 36517}, {'raceId': 861, 'driverId': 18, 'stop': 4, 'lap_pitstops': 24, 'time_pitstops': '17:50:04', 'duration': 23509000000, 'milliseconds_pitstops': 23509}  ... displaying 10 of 8975 total bound parameter sets ...  {'raceId': 953, 'driverId': 837, 'stop': 2, 'lap_pitstops': 34, 'time_pitstops': '15:00:18', 'duration': 27380000000, 'milliseconds_pitstops': 27380}, {'raceId': 953, 'driverId': 837, 'stop': 3, 'lap_pitstops': 47, 'time_pitstops': '15:21:24', 'duration': 26292000000, 'milliseconds_pitstops': 26292})]
(Background on this error at: https://sqlalche.me/e/14/f405); 401)
[2024-05-31T14:48:51.553+0000] {local_task_job_runner.py:240} INFO - Task exited with return code 1
[2024-05-31T14:48:51.564+0000] {taskinstance.py:3498} INFO - 0 downstream tasks scheduled from follow-on schedule check
[2024-05-31T14:48:51.566+0000] {local_task_job_runner.py:222} INFO - ::endgroup::
